Validation report for ogc.ogc-utils.prov - Provenance Chain
Generated 2024-02-14T13:13:49.406967+00:00
=== Files ===
Using example_2_1.json from examples
JSON-LD context is present - uplifting
Output JSON-LD example_2_1.jsonld created
Output Turtle example_2_1.ttl created
=== End Files ===

=== JSON Schema ===
Using the following JSON Schema: #/$defs/Activity
=== End JSON Schema ===

=== Unknown errors ===

** Validation error **
Traceback (most recent call last):
,  File "/venv/lib/python3.10/site-packages/jsonschema/validators.py", line 909, in resolve_from_url
    document = self.store[url]
,  File "/venv/lib/python3.10/site-packages/jsonschema/_utils.py", line 28, in __getitem__
    return self.store[self.normalize(uri)]
,KeyError: 'bblocks://ogc.ogc-utils.iri-or-curie'
,
During handling of the above exception, another exception occurred:

,Traceback (most recent call last):
,  File "/venv/lib/python3.10/site-packages/jsonschema/validators.py", line 912, in resolve_from_url
    document = self.resolve_remote(url)
,  File "/src/ogc/bblocks/validate.py", line 889, in resolve_remote
    with urlopen(uri) as url:
,  File "/usr/local/lib/python3.10/urllib/request.py", line 216, in urlopen
    return opener.open(url, data, timeout)
,  File "/usr/local/lib/python3.10/urllib/request.py", line 519, in open
    response = self._open(req, data)
,  File "/usr/local/lib/python3.10/urllib/request.py", line 541, in _open
    return self._call_chain(self.handle_open, 'unknown',
,  File "/usr/local/lib/python3.10/urllib/request.py", line 496, in _call_chain
    result = func(*args)
,  File "/usr/local/lib/python3.10/urllib/request.py", line 1419, in unknown_open
    raise URLError('unknown url type: %s' % type)
,urllib.error.URLError: <urlopen error unknown url type: bblocks>
,
During handling of the above exception, another exception occurred:

,Traceback (most recent call last):
,  File "/src/ogc/bblocks/validate.py", line 517, in validate_inner
    validate_json(json_doc, schema_validator)
,  File "/src/ogc/bblocks/validate.py", line 912, in validate_json
    error = jsonschema.exceptions.best_match(validator.iter_errors(instance))
,  File "/venv/lib/python3.10/site-packages/jsonschema/exceptions.py", line 384, in best_match
    best = next(errors, None)
,  File "/venv/lib/python3.10/site-packages/jsonschema/validators.py", line 288, in iter_errors
    for error in errors:
,  File "/venv/lib/python3.10/site-packages/jsonschema/_validators.py", line 298, in ref
    yield from validator.descend(instance, resolved)
,  File "/venv/lib/python3.10/site-packages/jsonschema/validators.py", line 305, in descend
    for error in self.evolve(schema=schema).iter_errors(instance):
,  File "/venv/lib/python3.10/site-packages/jsonschema/validators.py", line 288, in iter_errors
    for error in errors:
,  File "/venv/lib/python3.10/site-packages/jsonschema/_validators.py", line 332, in properties
    yield from validator.descend(
,  File "/venv/lib/python3.10/site-packages/jsonschema/validators.py", line 305, in descend
    for error in self.evolve(schema=schema).iter_errors(instance):
,  File "/venv/lib/python3.10/site-packages/jsonschema/validators.py", line 288, in iter_errors
    for error in errors:
,  File "/venv/lib/python3.10/site-packages/jsonschema/_validators.py", line 298, in ref
    yield from validator.descend(instance, resolved)
,  File "/venv/lib/python3.10/site-packages/jsonschema/validators.py", line 305, in descend
    for error in self.evolve(schema=schema).iter_errors(instance):
,  File "/venv/lib/python3.10/site-packages/jsonschema/validators.py", line 288, in iter_errors
    for error in errors:
,  File "/venv/lib/python3.10/site-packages/jsonschema/_validators.py", line 294, in ref
    scope, resolved = validator.resolver.resolve(ref)
,  File "/venv/lib/python3.10/site-packages/jsonschema/validators.py", line 898, in resolve
    return url, self._remote_cache(url)
,  File "/venv/lib/python3.10/site-packages/jsonschema/validators.py", line 914, in resolve_from_url
    raise exceptions.RefResolutionError(exc)
,jsonschema.exceptions.RefResolutionError: <urlopen error unknown url type: bblocks>
,
During handling of the above exception, another exception occurred:

,Traceback (most recent call last):
,  File "/src/ogc/bblocks/validate.py", line 640, in _validate_resource
    validate_inner()
,  File "/src/ogc/bblocks/validate.py", line 537, in validate_inner
    'errorMessage': e.message,
,AttributeError: 'RefResolutionError' object has no attribute 'message'

=== End Unknown errors ===

